ReflectionEntityInstantiator should actually throw created exception
In the catch block a new exception is instanciated, which I assume should be thrown, but misses the throw keyword and therefore currently does nothing.
https://github.com/SpringSource/spring-data-commons/blob/master/src/main/java/org/springframework/data/convert/ReflectionEntityInstantiator.java#L64
Simplistic test that demonstrates this: https://github.com/SpringSource/spring-data-commons/pull/25/files